Workbook

Sheet Stock Market Data
A1: STOCK MARKET PERFORMANCE TRACKER — Minor Project
A2: S.No | B2: Company Name | C2: Ticker | D2: Sector | E2: Date | F2: Open (₹) | G2: High (₹) | H2: Low (₹) | I2: Close (₹) | J2: Volume | K2: Market Cap (Cr) | L2: P/E Ratio | M2: Change (₹) | N2: Change (%)
A3: 1 | B3: Reliance Industries | C3: RELIANCE | D3: Energy | E3: 45658 | F3: 2740.57 | G3: 2742.05 | H3: 2703.12 | I3: 2708.18 | J3: 11436994 | K3: 2418018 | L3: 31.6 | M3: =I3-F3 -> -32.39 | N3: =M3/F3 -> -0.011818709
A4: 2 | B4: Tata Consultancy Services | C4: TCS | D4: IT | E4: 45660 | F4: 3948.25 | G4: 3981.36 | H4: 3928.58 | I4: 3964.31 | J4: 13098418 | K4: 1423086 | L4: 46 | M4: =I4-F4 -> 16.06 | N4: =M4/F4 -> 0.0040676249
A5: 3 | B5: HDFC Bank | C5: HDFCBANK | D5: Banking | E5: 45662 | F5: 1673.03 | G5: 1691.74 | H5: 1661.06 | I5: 1661.6 | J5: 6141215 | K5: 1258788 | L5: 19.4 | M5: =I5-F5 -> -11.43 | N5: =M5/F5 -> -0.0068319157
A6: 4 | B6: Infosys | C6: INFY | D6: IT | E6: 45664 | F6: 1437.23 | G6: 1464.38 | H6: 1415.18 | I6: 1458.37 | J6: 14222580 | K6: 603463 | L6: 55.4 | M6: =I6-F6 -> 21.14 | N6: =M6/F6 -> 0.01470885
A7: 5 | B7: ICICI Bank | C7: ICICIBANK | D7: Banking | E7: 45666 | F7: 1070.57 | G7: 1085.04 | H7: 1052.67 | I7: 1077.19 | J7: 5232314 | K7: 759162 | L7: 23.8 | M7: =I7-F7 -> 6.62 | N7: =M7/F7 -> 0.0061836218
A8: 6 | B8: Hindustan Unilever | C8: HINDUNILVR | D8: FMCG | E8: 45668 | F8: 2374.62 | G8: 2400.16 | H8: 2325.88 | I8: 2360.61 | J8: 13071485 | K8: 550809 | L8: 16.2 | M8: =I8-F8 -> -14.01 | N8: =M8/F8 -> -0.0058998914
A9: 7 | B9: ITC Ltd | C9: ITC | D9: FMCG | E9: 45670 | F9: 437.55 | G9: 438.65 | H9: 430.67 | I9: 436.32 | J9: 9366711 | K9: 542976 | L9: 59 | M9: =I9-F9 -> -1.23 | N9: =M9/F9 -> -0.0028111073
A10: 8 | B10: Larsen & Toubro | C10: LT | D10: Infrastructure | E10: 45672 | F10: 3424.08 | G10: 3429.35 | H10: 3385.75 | I10: 3385.78 | J10: 3058458 | K10: 477992 | L10: 46.5 | M10: =I10-F10 -> -38.3 | N10: =M10/F10 -> -0.011185486
A11: 9 | B11: State Bank of India | C11: SBIN | D11: Banking | E11: 45674 | F11: 751.52 | G11: 765.1 | H11: 741.98 | I11: 762.57 | J11: 14220339 | K11: 682299 | L11: 21.7 | M11: =I11-F11 -> 11.05 | N11: =M11/F11 -> 0.014703534
A12: 10 | B12: Bajaj Finance | C12: BAJFINANCE | D12: Finance | E12: 45676 | F12: 6817.37 | G12: 6915 | H12: 6730.8 | I12: 6864.59 | J12: 3576305 | K12: 423989 | L12: 45.1 | M12: =I12-F12 -> 47.22 | N12: =M12/F12 -> 0.0069264247
A13: 11 | B13: Wipro | C13: WIPRO | D13: IT | E13: 45678 | F13: 492.44 | G13: 495.69 | H13: 488.56 | I13: 490.85 | J13: 4010279 | K13: 255651 | L13: 28.4 | M13: =I13-F13 -> -1.59 | N13: =M13/F13 -> -0.0032288198
A14: 12 | B14: Asian Paints | C14: ASIANPAINT | D14: Materials | E14: 45680 | F14: 2726.52 | G14: 2794.27 | H14: 2671.61 | I14: 2694.6 | J14: 4270233 | K14: 257912 | L14: 50.7 | M14: =I14-F14 -> -31.92 | N14: =M14/F14 -> -0.011707231
... A102: 100 | B102: Bharti Airtel | C102: BHARTIARTL | D102: Telecom | E102: 45856 | F102: 1662.14 | G102: 1703.14 | H102: 1623.06 | I102: 1674.55 | J102: 746592 | K102: 936733 | L102: 34.5 | M102: =I102-F102 -> 12.41 | N102: =M102/F102 -> 0.0074662784

Sheet Summary
A1: SUMMARY STATISTICS
A2: Metric | B2: Formula | C2: Value
A3: Total Entries | B3: COUNT | C3: =COUNTA('Stock Market Data'!A3:A102) -> 100
A4: Avg Close Price (₹) | B4: AVERAGE | C4: =AVERAGE('Stock Market Data'!I3:I102) -> 2465.6363
A5: Max Close Price (₹) | B5: MAX | C5: =MAX('Stock Market Data'!I3:I102) -> 11154.47
A6: Min Close Price (₹) | B6: MIN | C6: =MIN('Stock Market Data'!I3:I102) -> 313.34
A7: Avg Volume | B7: AVERAGE | C7: =AVERAGE('Stock Market Data'!J3:J102) -> 8035657.4
A8: Total Volume | B8: SUM | C8: =SUM('Stock Market Data'!J3:J102) -> 803565739
A9: Avg P/E Ratio | B9: AVERAGE | C9: =AVERAGE('Stock Market Data'!L3:L102) -> 38.213
A10: Positive Days | B10: COUNTIF | C10: =COUNTIF('Stock Market Data'!N3:N102,">0") -> 46
A11: Negative Days | B11: COUNTIF | C11: =COUNTIF('Stock Market Data'!N3:N102,"<0") -> 53
A12: Avg Daily Change (%) | B12: AVERAGE | C12: =AVERAGE('Stock Market Data'!N3:N102) -> -0.0013008431

Sheet Charts & Analysis
A1: 📊 STOCK MARKET — DATA ANALYSIS CHARTS
A3: Total Volume by Company | D3: Total Trading Volume by Company | G3: Avg P/E Ratio by Sector | J3: Price Range by Company (High / Low / Avg Close)
D4: Ticker | E4: Total Volume | G4: Sector | H4: Avg P/E | J4: Ticker | K4: Avg High | L4: Avg Low | M4: Avg Close
A5: Auto | B5: 10992.37 | D5: ADANIPORTS | E5: 34932347 | G5: Auto | H5: 36.3 | J5: ADANIPORTS | K5: 1260.98 | L5: 1228.93 | M5: 1246.55
A6: Banking | B6: 1300.72 | D6: ASIANPAINT | E6: 37174907 | G6: Banking | H6: 37.9 | J6: ASIANPAINT | K6: 2855.3 | L6: 2759.82 | M6: 2806.74
A7: Consumer | B7: 3457.29 | D7: BAJFINANCE | E7: 32033644 | G7: Consumer | H7: 41.9 | J7: BAJFINANCE | K7: 6907.12 | L7: 6717.53 | M7: 6804.66
A8: Energy | B8: 2781.82 | D8: BHARTIARTL | E8: 20207931 | G8: Energy | H8: 37.7 | J8: BHARTIARTL | K8: 1662.7 | L8: 1610.47 | M8: 1645.27
A9: FMCG | B9: 1424.5 | D9: HDFCBANK | E9: 38430866 | G9: FMCG | H9: 42.5 | J9: HDFCBANK | K9: 1659.2 | L9: 1631.29 | M9: 1638.02
A10: Finance | B10: 6804.66 | D10: HINDUNILVR | E10: 46369614 | G10: Finance | H10: 29.6 | J10: HINDUNILVR | K10: 2426.07 | L10: 2370.1 | M10: 2404.94
A11: IT | B11: 1953.04 | D11: ICICIBANK | E11: 27874713 | G11: IT | H11: 38.3 | J11: ICICIBANK | K11: 1072.81 | L11: 1049.11 | M11: 1064.04
A12: Infrastructure | B12: 2314.03 | D12: INFY | E12: 46990478 | G12: Infrastructure | H12: 39.5 | J12: INFY | K12: 1470.85 | L12: 1427.86 | M12: 1453.11
A13: Materials | B13: 2806.74 | D13: ITC | E13: 51496154 | G13: Materials | H13: 34.8 | J13: ITC | K13: 451.09 | L13: 439.85 | M13: 444.06
A14: Pharma | B14: 1601.54 | D14: KOTAKBANK | E14: 25444004 | G14: Pharma | H14: 45.1 | J14: KOTAKBANK | K14: 1766.88 | L14: 1724.46 | M14: 1738.05
A15: Telecom | B15: 1645.27 | D15: LT | E15: 46110921 | G15: Telecom | H15: 34.2 | J15: LT | K15: 3426.57 | L15: 3343.12 | M15: 3381.51
A16: Utilities | B16: 341.99 | D16: MARUTI | E16: 41497911 | G16: Utilities | H16: 37.1 | J16: MARUTI | K16: 11115.48 | L16: 10917.61 | M16: 10992.37
D17: NTPC | E17: 30581862 | J17: NTPC | K17: 366.79 | L17: 357.35 | M17: 361.92
D18: POWERGRID | E18: 58010429 | J18: POWERGRID | K18: 325.22 | L18: 318.49 | M18: 322.05
A19: Positive vs Negative Days per Company | D19: RELIANCE | E19: 40794474 | J19: RELIANCE | K19: 2824.41 | L19: 2761.22 | M19: 2781.82
A20: Ticker | B20: Positive Days | C20: Negative Days | D20: SBIN | E20: 57296979 | J20: SBIN | K20: 771.13 | L20: 755.75 | M20: 762.76
A21: ADANIPORTS | B21: 2 | C21: 3 | D21: SUNPHARMA | E21: 41954653 | J21: SUNPHARMA | K21: 1626.15 | L21: 1583.48 | M21: 1601.54
A22: ASIANPAINT | B22: 3 | C22: 2 | D22: TCS | E22: 48761349 | J22: TCS | K22: 3970.52 | L22: 3875.33 | M22: 3926.14
A23: BAJFINANCE | B23: 2 | C23: 3 | D23: TITAN | E23: 46927880 | J23: TITAN | K23: 3525.79 | L23: 3421.2 | M23: 3457.29
A24: BHARTIARTL | B24: 4 | C24: 1 | D24: WIPRO | E24: 30674623 | J24: WIPRO | K24: 486.93 | L24: 474.04 | M24: 479.88
A25: HDFCBANK | B25: 1 | C25: 4
A26: HINDUNILVR | B26: 2 | C26: 3
A27: ICICIBANK | B27: 4 | C27: 1
A28: INFY | B28: 3 | C28: 2
A29: ITC | B29: 4 | C29: 1
A30: KOTAKBANK | B30: 2 | C30: 3
A31: LT | B31: 2 | C31: 3
A32: MARUTI | B32: 1 | C32: 4
A33: NTPC | B33: 2 | C33: 3
A34: POWERGRID | B34: 1 | C34: 4
A35: RELIANCE | B35: 2 | C35: 3
A36: SBIN | B36: 2 | C36: 3
... A40: WIPRO | B40: 2 | C40: 3
A43: Sector | B43: Count
A44: Auto | B44: 5
A45: Banking | B45: 20
A46: Consumer | B46: 5
...
